[2022-03-27 06:28:27,659] {taskinstance.py:1037} INFO - Dependencies all met for <TaskInstance: census_consumer_complaint.RemoteZipCsvExampleGen scheduled__2022-03-26T00:00:00+00:00 [queued]>
[2022-03-27 06:28:27,667] {taskinstance.py:1037} INFO - Dependencies all met for <TaskInstance: census_consumer_complaint.RemoteZipCsvExampleGen scheduled__2022-03-26T00:00:00+00:00 [queued]>
[2022-03-27 06:28:27,667] {taskinstance.py:1243} INFO - 
--------------------------------------------------------------------------------
[2022-03-27 06:28:27,667] {taskinstance.py:1244} INFO - Starting attempt 1 of 1
[2022-03-27 06:28:27,667] {taskinstance.py:1245} INFO - 
--------------------------------------------------------------------------------
[2022-03-27 06:28:27,678] {taskinstance.py:1264} INFO - Executing <Task(AirflowComponent): RemoteZipCsvExampleGen> on 2022-03-26 00:00:00+00:00
[2022-03-27 06:28:27,686] {standard_task_runner.py:52} INFO - Started process 95 to run task
[2022-03-27 06:28:27,692] {standard_task_runner.py:76} INFO - Running: ['***', 'tasks', 'run', 'census_consumer_complaint', 'RemoteZipCsvExampleGen', 'scheduled__2022-03-26T00:00:00+00:00', '--job-id', '103', '--raw', '--subdir', 'DAGS_FOLDER/census_consumer_complaint.py', '--cfg-path', '/tmp/tmp88y6dhhf', '--error-file', '/tmp/tmpmj6g7z2e']
[2022-03-27 06:28:27,692] {standard_task_runner.py:77} INFO - Job 103: Subtask RemoteZipCsvExampleGen
[2022-03-27 06:28:27,742] {logging_mixin.py:109} INFO - Running <TaskInstance: census_consumer_complaint.RemoteZipCsvExampleGen scheduled__2022-03-26T00:00:00+00:00 [running]> on host 691464fec4e5
[2022-03-27 06:28:27,780] {taskinstance.py:1431} INFO - Exporting the following env vars:
AIRFLOW_CTX_DAG_OWNER=***
AIRFLOW_CTX_DAG_ID=census_consumer_complaint
AIRFLOW_CTX_TASK_ID=RemoteZipCsvExampleGen
AIRFLOW_CTX_EXECUTION_DATE=2022-03-26T00:00:00+00:00
AIRFLOW_CTX_DAG_RUN_ID=scheduled__2022-03-26T00:00:00+00:00
[2022-03-27 06:28:27,781] {base_component_launcher.py:190} INFO - Running driver for RemoteZipCsvExampleGen
[2022-03-27 06:28:27,785] {metadata_store.py:101} INFO - MetadataStore with DB connection initialized
[2022-03-27 06:28:27,786] {utils.py:698} INFO - select span and version = (0, None)
[2022-03-27 06:28:27,786] {utils.py:707} INFO - latest span and version = (0, None)
[2022-03-27 06:28:27,801] {base_component_launcher.py:196} INFO - Running executor for RemoteZipCsvExampleGen
[2022-03-27 06:28:27,802] {base_example_gen_executor.py:272} INFO - Generating examples.
[2022-03-27 06:28:27,804] {pipeline.py:188} INFO - Missing pipeline option (runner). Executing pipeline using the default runner: DirectRunner.
[2022-03-27 06:28:27,812] {logging_mixin.py:109} INFO - Downloading file in  /opt/***/zip_to_csv
[2022-03-27 06:28:27,816] {taskinstance.py:1718} ERROR - Task failed with exception
Traceback (most recent call last):
  File "/usr/local/lib/python3.7/urllib/request.py", line 1350, in do_open
    encode_chunked=req.has_header('Transfer-encoding'))
  File "/usr/local/lib/python3.7/http/client.py", line 1281, in request
    self._send_request(method, url, body, headers, encode_chunked)
  File "/usr/local/lib/python3.7/http/client.py", line 1327, in _send_request
    self.endheaders(body, encode_chunked=encode_chunked)
  File "/usr/local/lib/python3.7/http/client.py", line 1276, in endheaders
    self._send_output(message_body, encode_chunked=encode_chunked)
  File "/usr/local/lib/python3.7/http/client.py", line 1036, in _send_output
    self.send(msg)
  File "/usr/local/lib/python3.7/http/client.py", line 976, in send
    self.connect()
  File "/usr/local/lib/python3.7/http/client.py", line 1443, in connect
    super().connect()
  File "/usr/local/lib/python3.7/http/client.py", line 948, in connect
    (self.host,self.port), self.timeout, self.source_address)
  File "/usr/local/lib/python3.7/socket.py", line 707, in create_connection
    for res in getaddrinfo(host, port, 0, SOCK_STREAM):
  File "/usr/local/lib/python3.7/socket.py", line 752, in getaddrinfo
    for res in _socket.getaddrinfo(host, port, family, type, proto, flags):
socket.gaierror: [Errno -3] Temporary failure in name resolution

During handling of the above exception, another exception occurred:

Traceback (most recent call last):
  File "/home/airflow/.local/lib/python3.7/site-packages/census_consumer_complaint_utils/utils.py", line 172, in download_dataset
    request.urlretrieve(zip_file_uri, zip_file_path)
  File "/usr/local/lib/python3.7/urllib/request.py", line 247, in urlretrieve
    with contextlib.closing(urlopen(url, data)) as fp:
  File "/usr/local/lib/python3.7/urllib/request.py", line 222, in urlopen
    return opener.open(url, data, timeout)
  File "/usr/local/lib/python3.7/urllib/request.py", line 525, in open
    response = self._open(req, data)
  File "/usr/local/lib/python3.7/urllib/request.py", line 543, in _open
    '_open', req)
  File "/usr/local/lib/python3.7/urllib/request.py", line 503, in _call_chain
    result = func(*args)
  File "/usr/local/lib/python3.7/urllib/request.py", line 1393, in https_open
    context=self._context, check_hostname=self._check_hostname)
  File "/usr/local/lib/python3.7/urllib/request.py", line 1352, in do_open
    raise URLError(err)
urllib.error.URLError: <urlopen error [Errno -3] Temporary failure in name resolution>

During handling of the above exception, another exception occurred:

Traceback (most recent call last):
  File "/home/airflow/.local/lib/python3.7/site-packages/airflow/models/taskinstance.py", line 1334, in _run_raw_task
    self._execute_task_with_callbacks(context)
  File "/home/airflow/.local/lib/python3.7/site-packages/airflow/models/taskinstance.py", line 1460, in _execute_task_with_callbacks
    result = self._execute_task(context, self.task)
  File "/home/airflow/.local/lib/python3.7/site-packages/airflow/models/taskinstance.py", line 1516, in _execute_task
    result = execute_callable(context=context)
  File "/home/airflow/.local/lib/python3.7/site-packages/airflow/operators/python.py", line 174, in execute
    return_value = self.execute_callable()
  File "/home/airflow/.local/lib/python3.7/site-packages/airflow/operators/python.py", line 188, in execute_callable
    return self.python_callable(*self.op_args, **self.op_kwargs)
  File "/home/airflow/.local/lib/python3.7/site-packages/tfx/orchestration/airflow/airflow_component.py", line 76, in _airflow_component_launcher
    launcher.launch()
  File "/home/airflow/.local/lib/python3.7/site-packages/tfx/orchestration/launcher/base_component_launcher.py", line 203, in launch
    copy.deepcopy(execution_decision.exec_properties))
  File "/home/airflow/.local/lib/python3.7/site-packages/tfx/orchestration/launcher/in_process_component_launcher.py", line 74, in _run_executor
    copy.deepcopy(input_dict), output_dict, copy.deepcopy(exec_properties))
  File "/home/airflow/.local/lib/python3.7/site-packages/tfx/components/example_gen/base_example_gen_executor.py", line 274, in Do
    example_splits = self.GenerateExamplesByBeam(pipeline, exec_properties)
  File "/home/airflow/.local/lib/python3.7/site-packages/tfx/components/example_gen/base_example_gen_executor.py", line 200, in GenerateExamplesByBeam
    | 'SplitData' >> beam.Partition(_PartitionFn, len(buckets), buckets,
  File "/home/airflow/.local/lib/python3.7/site-packages/apache_beam/transforms/ptransform.py", line 1092, in __ror__
    return self.transform.__ror__(pvalueish, self.label)
  File "/home/airflow/.local/lib/python3.7/site-packages/apache_beam/transforms/ptransform.py", line 614, in __ror__
    result = p.apply(self, pvalueish, label)
  File "/home/airflow/.local/lib/python3.7/site-packages/apache_beam/pipeline.py", line 662, in apply
    return self.apply(transform, pvalueish)
  File "/home/airflow/.local/lib/python3.7/site-packages/apache_beam/pipeline.py", line 708, in apply
    pvalueish_result = self.runner.apply(transform, pvalueish, self._options)
  File "/home/airflow/.local/lib/python3.7/site-packages/apache_beam/runners/runner.py", line 185, in apply
    return m(transform, input, options)
  File "/home/airflow/.local/lib/python3.7/site-packages/apache_beam/runners/runner.py", line 215, in apply_PTransform
    return transform.expand(input)
  File "/home/airflow/.local/lib/python3.7/site-packages/apache_beam/transforms/ptransform.py", line 996, in expand
    return self._fn(pcoll, *args, **kwargs)
  File "/home/airflow/.local/lib/python3.7/site-packages/census_consumer_complaint_custom_component/example_gen/remote_zip_csv_example_gen/executor.py", line 61, in _ZipToExample
    zip_file_path = download_dataset(zip_file_uri, input_base_uri)
  File "/home/airflow/.local/lib/python3.7/site-packages/census_consumer_complaint_utils/utils.py", line 175, in download_dataset
    raise ValueError('Failed to download dataset from {}. {}'.format(zip_file_uri, e))
ValueError: Failed to download dataset from https://files.consumerfinance.gov/ccdb/complaints.csv.zip. <urlopen error [Errno -3] Temporary failure in name resolution>
[2022-03-27 06:28:27,830] {taskinstance.py:1282} INFO - Marking task as FAILED. dag_id=census_consumer_complaint, task_id=RemoteZipCsvExampleGen, execution_date=20220326T000000, start_date=20220327T062827, end_date=20220327T062827
[2022-03-27 06:28:27,841] {standard_task_runner.py:92} ERROR - Failed to execute job 103 for task RemoteZipCsvExampleGen
Traceback (most recent call last):
  File "/usr/local/lib/python3.7/urllib/request.py", line 1350, in do_open
    encode_chunked=req.has_header('Transfer-encoding'))
  File "/usr/local/lib/python3.7/http/client.py", line 1281, in request
    self._send_request(method, url, body, headers, encode_chunked)
  File "/usr/local/lib/python3.7/http/client.py", line 1327, in _send_request
    self.endheaders(body, encode_chunked=encode_chunked)
  File "/usr/local/lib/python3.7/http/client.py", line 1276, in endheaders
    self._send_output(message_body, encode_chunked=encode_chunked)
  File "/usr/local/lib/python3.7/http/client.py", line 1036, in _send_output
    self.send(msg)
  File "/usr/local/lib/python3.7/http/client.py", line 976, in send
    self.connect()
  File "/usr/local/lib/python3.7/http/client.py", line 1443, in connect
    super().connect()
  File "/usr/local/lib/python3.7/http/client.py", line 948, in connect
    (self.host,self.port), self.timeout, self.source_address)
  File "/usr/local/lib/python3.7/socket.py", line 707, in create_connection
    for res in getaddrinfo(host, port, 0, SOCK_STREAM):
  File "/usr/local/lib/python3.7/socket.py", line 752, in getaddrinfo
    for res in _socket.getaddrinfo(host, port, family, type, proto, flags):
socket.gaierror: [Errno -3] Temporary failure in name resolution

During handling of the above exception, another exception occurred:

Traceback (most recent call last):
  File "/home/airflow/.local/lib/python3.7/site-packages/census_consumer_complaint_utils/utils.py", line 172, in download_dataset
    request.urlretrieve(zip_file_uri, zip_file_path)
  File "/usr/local/lib/python3.7/urllib/request.py", line 247, in urlretrieve
    with contextlib.closing(urlopen(url, data)) as fp:
  File "/usr/local/lib/python3.7/urllib/request.py", line 222, in urlopen
    return opener.open(url, data, timeout)
  File "/usr/local/lib/python3.7/urllib/request.py", line 525, in open
    response = self._open(req, data)
  File "/usr/local/lib/python3.7/urllib/request.py", line 543, in _open
    '_open', req)
  File "/usr/local/lib/python3.7/urllib/request.py", line 503, in _call_chain
    result = func(*args)
  File "/usr/local/lib/python3.7/urllib/request.py", line 1393, in https_open
    context=self._context, check_hostname=self._check_hostname)
  File "/usr/local/lib/python3.7/urllib/request.py", line 1352, in do_open
    raise URLError(err)
urllib.error.URLError: <urlopen error [Errno -3] Temporary failure in name resolution>

During handling of the above exception, another exception occurred:

Traceback (most recent call last):
  File "/home/airflow/.local/lib/python3.7/site-packages/airflow/task/task_runner/standard_task_runner.py", line 85, in _start_by_fork
    args.func(args, dag=self.dag)
  File "/home/airflow/.local/lib/python3.7/site-packages/airflow/cli/cli_parser.py", line 48, in command
    return func(*args, **kwargs)
  File "/home/airflow/.local/lib/python3.7/site-packages/airflow/utils/cli.py", line 92, in wrapper
    return f(*args, **kwargs)
  File "/home/airflow/.local/lib/python3.7/site-packages/airflow/cli/commands/task_command.py", line 298, in task_run
    _run_task_by_selected_method(args, dag, ti)
  File "/home/airflow/.local/lib/python3.7/site-packages/airflow/cli/commands/task_command.py", line 107, in _run_task_by_selected_method
    _run_raw_task(args, ti)
  File "/home/airflow/.local/lib/python3.7/site-packages/airflow/cli/commands/task_command.py", line 184, in _run_raw_task
    error_file=args.error_file,
  File "/home/airflow/.local/lib/python3.7/site-packages/airflow/utils/session.py", line 70, in wrapper
    return func(*args, session=session, **kwargs)
  File "/home/airflow/.local/lib/python3.7/site-packages/airflow/models/taskinstance.py", line 1334, in _run_raw_task
    self._execute_task_with_callbacks(context)
  File "/home/airflow/.local/lib/python3.7/site-packages/airflow/models/taskinstance.py", line 1460, in _execute_task_with_callbacks
    result = self._execute_task(context, self.task)
  File "/home/airflow/.local/lib/python3.7/site-packages/airflow/models/taskinstance.py", line 1516, in _execute_task
    result = execute_callable(context=context)
  File "/home/airflow/.local/lib/python3.7/site-packages/airflow/operators/python.py", line 174, in execute
    return_value = self.execute_callable()
  File "/home/airflow/.local/lib/python3.7/site-packages/airflow/operators/python.py", line 188, in execute_callable
    return self.python_callable(*self.op_args, **self.op_kwargs)
  File "/home/airflow/.local/lib/python3.7/site-packages/tfx/orchestration/airflow/airflow_component.py", line 76, in _airflow_component_launcher
    launcher.launch()
  File "/home/airflow/.local/lib/python3.7/site-packages/tfx/orchestration/launcher/base_component_launcher.py", line 203, in launch
    copy.deepcopy(execution_decision.exec_properties))
  File "/home/airflow/.local/lib/python3.7/site-packages/tfx/orchestration/launcher/in_process_component_launcher.py", line 74, in _run_executor
    copy.deepcopy(input_dict), output_dict, copy.deepcopy(exec_properties))
  File "/home/airflow/.local/lib/python3.7/site-packages/tfx/components/example_gen/base_example_gen_executor.py", line 274, in Do
    example_splits = self.GenerateExamplesByBeam(pipeline, exec_properties)
  File "/home/airflow/.local/lib/python3.7/site-packages/tfx/components/example_gen/base_example_gen_executor.py", line 200, in GenerateExamplesByBeam
    | 'SplitData' >> beam.Partition(_PartitionFn, len(buckets), buckets,
  File "/home/airflow/.local/lib/python3.7/site-packages/apache_beam/transforms/ptransform.py", line 1092, in __ror__
    return self.transform.__ror__(pvalueish, self.label)
  File "/home/airflow/.local/lib/python3.7/site-packages/apache_beam/transforms/ptransform.py", line 614, in __ror__
    result = p.apply(self, pvalueish, label)
  File "/home/airflow/.local/lib/python3.7/site-packages/apache_beam/pipeline.py", line 662, in apply
    return self.apply(transform, pvalueish)
  File "/home/airflow/.local/lib/python3.7/site-packages/apache_beam/pipeline.py", line 708, in apply
    pvalueish_result = self.runner.apply(transform, pvalueish, self._options)
  File "/home/airflow/.local/lib/python3.7/site-packages/apache_beam/runners/runner.py", line 185, in apply
    return m(transform, input, options)
  File "/home/airflow/.local/lib/python3.7/site-packages/apache_beam/runners/runner.py", line 215, in apply_PTransform
    return transform.expand(input)
  File "/home/airflow/.local/lib/python3.7/site-packages/apache_beam/transforms/ptransform.py", line 996, in expand
    return self._fn(pcoll, *args, **kwargs)
  File "/home/airflow/.local/lib/python3.7/site-packages/census_consumer_complaint_custom_component/example_gen/remote_zip_csv_example_gen/executor.py", line 61, in _ZipToExample
    zip_file_path = download_dataset(zip_file_uri, input_base_uri)
  File "/home/airflow/.local/lib/python3.7/site-packages/census_consumer_complaint_utils/utils.py", line 175, in download_dataset
    raise ValueError('Failed to download dataset from {}. {}'.format(zip_file_uri, e))
ValueError: Failed to download dataset from https://files.consumerfinance.gov/ccdb/complaints.csv.zip. <urlopen error [Errno -3] Temporary failure in name resolution>
[2022-03-27 06:28:27,867] {local_task_job.py:154} INFO - Task exited with return code 1
[2022-03-27 06:28:27,918] {local_task_job.py:264} INFO - 0 downstream tasks scheduled from follow-on schedule check
